Workbook

Sheet FND Calendario Dinámico
A1: CALENDARIO FND AUTOMÁTICO - MODELO AVANZADO
A2: Cálculo inteligente del Primer Día de Notificación (FND) considerando feriados de la Bolsa de Chicago (CME)
A4: Año del Contrato: | B4: 2026
A6: Trigo (Chi, KC, MN Wheat) [Ticker: W / KW]
A7: Mes Contrato | B7: Letra | C7: Fecha FND Ajustada (Fórmulas + Feriados CME) | D7: Código Contrato (Ticker)
A8: Marzo | B8: H | C8: =WORKDAY.INTL(DATE($B$4, 3, 1), -1, 1, 'Feriados CME'!$A$5:$A$43) -> 46080 | D8: ="W"&B8&RIGHT($B$4,2) -> WH26
A9: Mayo | B9: K | C9: =WORKDAY.INTL(DATE($B$4, 5, 1), -1, 1, 'Feriados CME'!$A$5:$A$43) -> 46142 | D9: ="W"&B9&RIGHT($B$4,2) -> WK26
A10: Julio | B10: N | C10: =WORKDAY.INTL(DATE($B$4, 7, 1), -1, 1, 'Feriados CME'!$A$5:$A$43) -> 46203 | D10: ="W"&B10&RIGHT($B$4,2) -> WN26
A11: Septiembre | B11: U | C11: =WORKDAY.INTL(DATE($B$4, 9, 1), -1, 1, 'Feriados CME'!$A$5:$A$43) -> 46265 | D11: ="W"&B11&RIGHT($B$4,2) -> WU26
A12: Diciembre | B12: Z | C12: =WORKDAY.INTL(DATE($B$4, 12, 1), -1, 1, 'Feriados CME'!$A$5:$A$43) -> 46356 | D12: ="W"&B12&RIGHT($B$4,2) -> WZ26
A14: Maíz (Corn) [Ticker: C / ZC]
A15: Mes Contrato | B15: Letra | C15: Fecha FND Ajustada (Fórmulas + Feriados CME) | D15: Código Contrato (Ticker)
A16: Marzo | B16: H | C16: =WORKDAY.INTL(DATE($B$4, 3, 1), -1, 1, 'Feriados CME'!$A$5:$A$43) -> 46080 | D16: ="C"&B16&RIGHT($B$4,2) -> CH26
A17: Mayo | B17: K | C17: =WORKDAY.INTL(DATE($B$4, 5, 1), -1, 1, 'Feriados CME'!$A$5:$A$43) -> 46142 | D17: ="C"&B17&RIGHT($B$4,2) -> CK26
A18: Julio | B18: N | C18: =WORKDAY.INTL(DATE($B$4, 7, 1), -1, 1, 'Feriados CME'!$A$5:$A$43) -> 46203 | D18: ="C"&B18&RIGHT($B$4,2) -> CN26
A19: Septiembre | B19: U | C19: =WORKDAY.INTL(DATE($B$4, 9, 1), -1, 1, 'Feriados CME'!$A$5:$A$43) -> 46265 | D19: ="C"&B19&RIGHT($B$4,2) -> CU26
A20: Diciembre | B20: Z | C20: =WORKDAY.INTL(DATE($B$4, 12, 1), -1, 1, 'Feriados CME'!$A$5:$A$43) -> 46356 | D20: ="C"&B20&RIGHT($B$4,2) -> CZ26
A22: Soja (Soybeans) [Ticker: S / ZS]
A23: Mes Contrato | B23: Letra | C23: Fecha FND Ajustada (Fórmulas + Feriados CME) | D23: Código Contrato (Ticker)
A24: Enero | B24: F | C24: =WORKDAY.INTL(DATE($B$4-1, 13, 1), -1, 1, 'Feriados CME'!$A$5:$A$43) -> 46022 | D24: ="S"&B24&RIGHT($B$4,2) -> SF26
A25: Marzo | B25: H | C25: =WORKDAY.INTL(DATE($B$4, 3, 1), -1, 1, 'Feriados CME'!$A$5:$A$43) -> 46080 | D25: ="S"&B25&RIGHT($B$4,2) -> SH26
A26: Mayo | B26: K | C26: =WORKDAY.INTL(DATE($B$4, 5, 1), -1, 1, 'Feriados CME'!$A$5:$A$43) -> 46142 | D26: ="S"&B26&RIGHT($B$4,2) -> SK26
A27: Julio | B27: N | C27: =WORKDAY.INTL(DATE($B$4, 7, 1), -1, 1, 'Feriados CME'!$A$5:$A$43) -> 46203 | D27: ="S"&B27&RIGHT($B$4,2) -> SN26
A28: Agosto | B28: Q | C28: =WORKDAY.INTL(DATE($B$4, 8, 1), -1, 1, 'Feriados CME'!$A$5:$A$43) -> 46234 | D28: ="S"&B28&RIGHT($B$4,2) -> SQ26
A29: Septiembre | B29: U | C29: =WORKDAY.INTL(DATE($B$4, 9, 1), -1, 1, 'Feriados CME'!$A$5:$A$43) -> 46265 | D29: ="S"&B29&RIGHT($B$4,2) -> SU26
A30: Noviembre | B30: X | C30: =WORKDAY.INTL(DATE($B$4, 11, 1), -1, 1, 'Feriados CME'!$A$5:$A$43) -> 46325 | D30: ="S"&B30&RIGHT($B$4,2) -> SX26
A32: Harina de Soja (Soybean Meal) [Ticker: SM / ZM]
A33: Mes Contrato | B33: Letra | C33: Fecha FND Ajustada (Fórmulas + Feriados CME) | D33: Código Contrato (Ticker)
A34: Enero | B34: F | C34: =WORKDAY.INTL(DATE($B$4-1, 13, 1), -1, 1, 'Feriados CME'!$A$5:$A$43) -> 46022 | D34: ="SM"&B34&RIGHT($B$4,2) -> SMF26
A35: Marzo | B35: H | C35: =WORKDAY.INTL(DATE($B$4, 3, 1), -1, 1, 'Feriados CME'!$A$5:$A$43) -> 46080 | D35: ="SM"&B35&RIGHT($B$4,2) -> SMH26
A36: Mayo | B36: K | C36: =WORKDAY.INTL(DATE($B$4, 5, 1), -1, 1, 'Feriados CME'!$A$5:$A$43) -> 46142 | D36: ="SM"&B36&RIGHT($B$4,2) -> SMK26
A37: Julio | B37: N | C37: =WORKDAY.INTL(DATE($B$4, 7, 1), -1, 1, 'Feriados CME'!$A$5:$A$43) -> 46203 | D37: ="SM"&B37&RIGHT($B$4,2) -> SMN26
A38: Agosto | B38: Q | C38: =WORKDAY.INTL(DATE($B$4, 8, 1), -1, 1, 'Feriados CME'!$A$5:$A$43) -> 46234 | D38: ="SM"&B38&RIGHT($B$4,2) -> SMQ26
A39: Septiembre | B39: U | C39: =WORKDAY.INTL(DATE($B$4, 9, 1), -1, 1, 'Feriados CME'!$A$5:$A$43) -> 46265 | D39: ="SM"&B39&RIGHT($B$4,2) -> SMU26
A40: Octubre | B40: V | C40: =WORKDAY.INTL(DATE($B$4, 10, 1), -1, 1, 'Feriados CME'!$A$5:$A$43) -> 46295 | D40: ="SM"&B40&RIGHT($B$4,2) -> SMV26
A41: Diciembre | B41: Z | C41: =WORKDAY.INTL(DATE($B$4, 12, 1), -1, 1, 'Feriados CME'!$A$5:$A$43) -> 46356 | D41: ="SM"&B41&RIGHT($B$4,2) -> SMZ26
A44: CÓDIGOS ESTÁNDAR DE MESES (GLOBAL / CME)
A45: Mes | B45: Letra | C45: Mes | D45: Letra
A46: Enero | B46: F | C46: Julio | D46: N
A47: Febrero | B47: G | C47: Agosto | D47: Q
...

Sheet Feriados CME
A1: FERIADOS BURSÁTILES CME / CBOT
A2: Días de cierre total de mercado aplicados para el cálculo exacto de días hábiles (WORKDAY.INTL / DIA.LABORAL.INTL)
A4: Fecha Feriado | B4: Festividad | C4: Año
A5: 45658 | B5: New Year's Day | C5: 2025
A6: 45677 | B6: Martin Luther King Jr. Day | C6: 2025
A7: 45705 | B7: Presidents' Day | C7: 2025
A8: 45765 | B8: Good Friday | C8: 2025
A9: 45803 | B9: Memorial Day | C9: 2025
A10: 45827 | B10: Juneteenth National Independence Day | C10: 2025
A11: 45842 | B11: Independence Day | C11: 2025
A12: 45901 | B12: Labor Day | C12: 2025
A13: 45988 | B13: Thanksgiving Day | C13: 2025
A14: 46016 | B14: Christmas Day | C14: 2025
A15: 46023 | B15: New Year's Day | C15: 2026
A16: 46041 | B16: Martin Luther King Jr. Day | C16: 2026
... A43: 47112 | B43: Christmas Day | C43: 2028
